<?xml version="1.0" ?>
<!-- =================================================================================== -->
<!-- |    This document was autogenerated by xacro from /home/hephaestus/ros2_ws/install/ur10e_cell_description/share/ur10e_cell_description/urdf/robot.urdf.xacro | -->
<!-- |    EDITING THIS FILE BY HAND IS NOT RECOMMENDED                                 | -->
<!-- =================================================================================== -->
<robot name="ur10e_cell">
    <material name="gray">
        <color rgba="0.7 0.7 0.7 1"/>
    </material>
    <material name="black">
        <color rgba="0 0 0 1"/>
    </material>
    <material name="darkgray">
        <color rgba="0.2 0.2 0.2 1"/>
    </material>
    <material name="aluminum">
        <color rgba="0.5 0.5 0.5 1"/>
    </material>
    <material name="w-gray">
        <color rgba="0.8 0.8 0.8 1.0"/>
    </material>
    <material name="plastic">
        <color rgba="0.1 0.1 0.1 1"/>
    </material>
    <material name="UR-blue">
        <color rgba="0.376 0.576 0.674 1.0"/>
    </material>
    <material name="white">
        <color rgba="1.0 1.0 1.0 1.0"/>
    </material>
    <material name="finger_pad">
        <color rgba="0.5 0.6 0.6 1"/>
    </material>
    <!--
      Base UR robot series xacro macro.

      NOTE this is NOT a URDF. It cannot directly be loaded by consumers
      expecting a flattened '.urdf' file. See the top-level '.xacro' for that
      (but note that .xacro must still be processed by the xacro command).

      This file models the base kinematic chain of a UR robot, which then gets
      parameterised by various configuration files to convert it into a UR3(e),
      UR5(e), UR10(e) or UR16e.

      NOTE the default kinematic parameters (i.e., link lengths, frame locations,
      offsets, etc) do not correspond to any particular robot. They are defaults
      only. There WILL be non-zero offsets between the Forward Kinematics results
      in TF (i.e., robot_state_publisher) and the values reported by the Teach
      Pendant.

      For accurate (and robot-specific) transforms, the 'kinematics_parameters_file'
      parameter MUST point to a .yaml file containing the appropriate values for
      the targeted robot.

      If using the UniversalRobots/Universal_Robots_ROS_Driver, follow the steps
      described in the readme of that repository to extract the kinematic
      calibration from the controller and generate the required .yaml file.

      Main author of the migration to yaml configs Ludovic Delval.

      Contributors to previous versions (in no particular order)

       - Denis Stogl
       - Lovro Ivanov
       - Felix Messmer
       - Kelsey Hawkins
       - Wim Meeussen
       - Shaun Edwards
       - Nadia Hammoudeh Garcia
       - Dave Hershberger
       - G. vd. Hoorn
       - Philip Long
       - Dave Coleman
       - Miguel Prada
       - Mathias Luedtke
       - Marcel Schnirring
       - Felix von Drigalski
       - Felix Exner
       - Jimmy Da Silva
       - Ajit Krisshna N L
       - Muhammad Asif Rana
    -->
    <!--
      NOTE the macro defined in this file is NOT part of the public API of this
            package. Users CANNOT rely on this file being available, or stored in
            this location. Nor can they rely on the existence of the macro.
    -->
    <link name="corrected_world"/>
    <joint name="world_joint" type="fixed">
        <origin rpy="0 0 0" xyz="0.43 0 -0.973"/>
        <parent link="corrected_world"/>
        <child link="world"/>
    </joint>
    <link name="world"/>
    <joint name="warehouse_joint" type="fixed">
        <origin rpy="0 0 0" xyz="0 0 0"/>
        <parent link="world"/>
        <child link="warehouse_link"/>
    </joint>
    <link name="warehouse_link">
        <visual>
            <origin rpy="0 0 0" xyz="0 0 0"/>
            <geometry>
                <mesh filename="../meshes/warehouse.stl" scale="0.0001 0.0001 0.0001"/>
            </geometry>
            <material name="w-gray"/>
        </visual>
    </link>
    <joint name="table_joint" type="fixed">
        <origin rpy="0 0 0" xyz="0 0 0"/>
        <parent link="world"/>
        <child link="table_link"/>
    </joint>
    <link name="table_link">
        <contact>
            <lateral_friction value="1.0"/>
            <rolling_friction value="0.001"/>
            <inertia_scaling value="2"/>
        </contact>
        <inertial>
            <origin rpy="0 0 0" xyz="0 0 0"/>
            <mass value="0.01"/>
            <inertia ixx="1" ixy="0" ixz="0" iyy="1" iyz="0" izz="1"/>
        </inertial>
        <visual>
            <origin rpy="0 0 0" xyz="-0.63 -0.4025 0"/>
            <geometry>
                <mesh filename="../meshes/table.stl" scale="0.001 0.001 0.001"/>
            </geometry>
            <material name="gray"/>
        </visual>
        <collision>
            <origin rpy="0 0 0" xyz="0 0 0.474"/>
            <geometry>
                <box size="1.26 0.805 0.948"/>
            </geometry>
        </collision>
    </link>
    <joint name="platform_joint" type="fixed">
        <origin rpy="0 0 0.0" xyz="-0.43 0.0 0.973"/>
        <parent link="table_link"/>
        <child link="platform_link"/>
    </joint>
    <link name="platform_link">
        <visual>
            <origin rpy="0 0 0" xyz="0 0 -0.0125"/>
            <geometry>
                <box size="0.34 0.34 0.025"/>
            </geometry>
            <material name="none">
                <color rgba="0 0 0 0"/>
            </material>
        </visual>

        <collision>
            <origin rpy="0 0 0" xyz="0 0 -0.0125"/>
            <geometry>
                <box size="0.34 0.34 0.025"/>
            </geometry>
        </collision>
    </link>

    <joint name="board_joint" type="fixed">
        <origin rpy="0 0 0.0" xyz="0.17 0.0 0.948"/>
        <parent link="table_link"/>
        <child link="board_link"/>
    </joint>
    <link name="board_link">
        <contact>
            <lateral_friction value="1.0"/>
            <inertia_scaling value="3.0"/>
        </contact>
        <inertial>
            <origin rpy="0 0 0" xyz="0 0 0"/>
            <mass value="0"/>
            <inertia ixx="1" ixy="0" ixz="0" iyy="1" iyz="0" izz="1"/>
        </inertial>
        <visual>
            <origin rpy="0 0 0" xyz="0 0 0"/>
            <geometry>
                <box size="0.684 0.64 0.025"/>
            </geometry>

            <material name="darkgray"/>
        </visual>
        <collision>
            <origin rpy="0 0 0" xyz="0 0 0"/>
            <geometry>
                <box size="0.684 0.64 0.025"/>
            </geometry>
        </collision>
    </link>
    <!-- Add URDF transmission elements (for ros_control) -->
    <!--<xacro:ur_arm_transmission prefix="${prefix}" hw_interface="${transmission_hw_interface}" />-->
    <!-- Placeholder for ros2_control transmission which don't yet exist -->
    <!-- links -  main serial chain -->
    <link name="base_link"/>
    <link name="base_link_inertia">
        <visual>
            <origin rpy="0 0 3.141592653589793" xyz="0 0 0"/>
            <geometry>
                <mesh filename="../meshes/ur10e/visual/base.dae"/>
            </geometry>
            <material name="gray"/>
        </visual>
        <collision>
            <origin rpy="0 0 3.141592653589793" xyz="0 0 0"/>
            <geometry>
                <mesh filename="../meshes/ur10e/collision/base.stl"/>
            </geometry>
        </collision>
        <inertial>
            <mass value="4.0"/>
            <origin rpy="0 0 0" xyz="0 0 0"/>
            <inertia ixx="0.0061063308908" ixy="0.0" ixz="0.0" iyy="0.0061063308908" iyz="0.0" izz="0.01125"/>
        </inertial>
    </link>
    <link name="shoulder_link">
        <visual>
            <origin rpy="0 0 3.141592653589793" xyz="0 0 0"/>
            <geometry>
                <mesh filename="../meshes/ur10e/visual/shoulder.dae"/>
            </geometry>
            <material name="UR-blue"/>
        </visual>
        <collision>
            <origin rpy="0 0 3.141592653589793" xyz="0 0 0"/>
            <geometry>
                <mesh filename="../meshes/ur10e/collision/shoulder.stl"/>
            </geometry>
        </collision>
        <inertial>
            <mass value="7.778"/>
            <origin rpy="0 0 0" xyz="0 0 0"/>
            <inertia ixx="0.03147431257693659" ixy="0.0" ixz="0.0" iyy="0.03147431257693659" iyz="0.0"
                     izz="0.021875624999999996"/>
        </inertial>
    </link>
    <link name="upper_arm_link">
        <visual>
            <origin rpy="1.5707963267948966 0 -1.5707963267948966" xyz="0 0 0.1762"/>
            <geometry>
                <mesh filename="../meshes/ur10e/visual/upperarm.dae"/>
            </geometry>
            <material name="gray"/>
        </visual>
        <collision>
            <origin rpy="1.5707963267948966 0 -1.5707963267948966" xyz="0 0 0.1762"/>
            <geometry>
                <mesh filename="../meshes/ur10e/collision/upperarm.stl"/>
            </geometry>
        </collision>
        <inertial>
            <mass value="12.93"/>
            <origin rpy="0 1.5707963267948966 0" xyz="-0.306 0.0 0.175"/>
            <inertia ixx="0.42175380379841093" ixy="0.0" ixz="0.0" iyy="0.42175380379841093" iyz="0.0"
                     izz="0.03636562499999999"/>
        </inertial>
    </link>
    <link name="forearm_link">
        <visual>
            <origin rpy="1.5707963267948966 0 -1.5707963267948966" xyz="0 0 0.0393"/>
            <geometry>
                <mesh filename="../meshes/ur10e/visual/forearm.dae"/>
            </geometry>
            <material name="gray"/>
        </visual>
        <collision>
            <origin rpy="1.5707963267948966 0 -1.5707963267948966" xyz="0 0 0.0393"/>
            <geometry>
                <mesh filename="../meshes/ur10e/collision/forearm.stl"/>
            </geometry>
        </collision>
        <inertial>
            <mass value="3.87"/>
            <origin rpy="0 1.5707963267948966 0" xyz="-0.285775 0.0 0.0393"/>
            <inertia ixx="0.11079302548902206" ixy="0.0" ixz="0.0" iyy="0.11079302548902206" iyz="0.0"
                     izz="0.010884375"/>
        </inertial>
    </link>
    <link name="wrist_1_link">
        <visual>
            <origin rpy="1.5707963267948966 0 0" xyz="0 0 -0.135"/>
            <geometry>
                <mesh filename="../meshes/ur10e/visual/wrist1.dae"/>
            </geometry>
            <material name="UR-blue"/>
        </visual>
        <collision>
            <origin rpy="1.5707963267948966 0 0" xyz="0 0 -0.135"/>
            <geometry>
                <mesh filename="../meshes/ur10e/collision/wrist1.stl"/>
            </geometry>
        </collision>
        <inertial>
            <mass value="1.96"/>
            <origin rpy="0 0 0" xyz="0 0 0"/>
            <inertia ixx="0.005108247956699999" ixy="0.0" ixz="0.0" iyy="0.005108247956699999" iyz="0.0"
                     izz="0.005512499999999999"/>
        </inertial>
    </link>
    <link name="wrist_2_link">
        <visual>
            <origin rpy="0 0 0" xyz="0 0 -0.12"/>
            <geometry>
                <mesh filename="../meshes/ur10e/visual/wrist2.dae"/>
            </geometry>
            <material name="gray"/>
        </visual>
        <collision>
            <origin rpy="0 0 0" xyz="0 0 -0.12"/>
            <geometry>
                <mesh filename="../meshes/ur10e/collision/wrist2.stl"/>
            </geometry>
        </collision>
        <inertial>
            <mass value="1.96"/>
            <origin rpy="0 0 0" xyz="0 0 0"/>
            <inertia ixx="0.005108247956699999" ixy="0.0" ixz="0.0" iyy="0.005108247956699999" iyz="0.0"
                     izz="0.005512499999999999"/>
        </inertial>
    </link>
    <link name="wrist_3_link">
        <visual>
            <origin rpy="1.5707963267948966 0 0" xyz="0 0 -0.1168"/>
            <geometry>
                <mesh filename="../meshes/ur10e/visual/wrist3.dae"/>
            </geometry>
            <material name="gray"/>
        </visual>
        <collision>
            <origin rpy="1.5707963267948966 0 0" xyz="0 0 -0.1168"/>
            <geometry>
                <mesh filename="../meshes/ur10e/collision/wrist3.stl"/>
            </geometry>
        </collision>
        <inertial>
            <mass value="0.202"/>
            <origin rpy="0 0 0" xyz="0.0 0.0 -0.025"/>
            <inertia ixx="0.00014434577559500002" ixy="0.0" ixz="0.0" iyy="0.00014434577559500002" iyz="0.0"
                     izz="0.00020452500000000002"/>
        </inertial>
    </link>
    <!-- base_joint fixes base_link to the environment -->
    <joint name="base_joint" type="fixed">
        <origin rpy="0 0 0" xyz="0 0 0"/>
        <parent link="platform_link"/>
        <child link="base_link"/>
    </joint>
    <!-- joints - main serial chain -->
    <joint name="base_link-base_link_inertia" type="fixed">
        <parent link="base_link"/>
        <child link="base_link_inertia"/>
        <!-- 'base_link' is REP-103 aligned (so X+ forward), while the internal
               frames of the robot/controller have X+ pointing backwards.
               Use the joint between 'base_link' and 'base_link_inertia' (a dummy
               link/frame) to introduce the necessary rotation over Z (of pi rad).
          -->
        <origin rpy="0 0 3.141592653589793" xyz="0 0 0"/>
    </joint>
    <joint name="shoulder_pan_joint" type="revolute">
        <parent link="base_link_inertia"/>
        <child link="shoulder_link"/>
        <origin rpy="0 0 0" xyz="0 0 0.1807"/>
        <axis xyz="0 0 1"/>
        <limit effort="330.0" lower="-6.283185307179586" upper="6.283185307179586" velocity="2.0943951023931953"/>
        <dynamics damping="0" friction="0"/>
    </joint>
    <joint name="shoulder_lift_joint" type="revolute">
        <parent link="shoulder_link"/>
        <child link="upper_arm_link"/>
        <origin rpy="1.570796327 0 0" xyz="0 0 0"/>
        <axis xyz="0 0 1"/>
        <limit effort="330.0" lower="-6.283185307179586" upper="6.283185307179586" velocity="2.0943951023931953"/>
        <dynamics damping="0" friction="0"/>
    </joint>
    <joint name="elbow_joint" type="revolute">
        <parent link="upper_arm_link"/>
        <child link="forearm_link"/>
        <origin rpy="0 0 0" xyz="-0.6127 0 0"/>
        <axis xyz="0 0 1"/>
        <limit effort="150.0" lower="-3.141592653589793" upper="3.141592653589793" velocity="3.141592653589793"/>
        <dynamics damping="0" friction="0"/>
    </joint>
    <joint name="wrist_1_joint" type="revolute">
        <parent link="forearm_link"/>
        <child link="wrist_1_link"/>
        <origin rpy="0 0 0" xyz="-0.57155 0 0.17415"/>
        <axis xyz="0 0 1"/>
        <limit effort="56.0" lower="-6.283185307179586" upper="6.283185307179586" velocity="3.141592653589793"/>
        <dynamics damping="0" friction="0"/>
    </joint>
    <joint name="wrist_2_joint" type="revolute">
        <parent link="wrist_1_link"/>
        <child link="wrist_2_link"/>
        <origin rpy="1.570796327 0 0" xyz="0 -0.11985 -2.458164590756244e-11"/>
        <axis xyz="0 0 1"/>
        <limit effort="56.0" lower="-6.283185307179586" upper="6.283185307179586" velocity="3.141592653589793"/>
        <dynamics damping="0" friction="0"/>
    </joint>
    <joint name="wrist_3_joint" type="revolute">
        <parent link="wrist_2_link"/>
        <child link="wrist_3_link"/>
        <origin rpy="1.570796326589793 3.141592653589793 3.141592653589793" xyz="0 0.11655 -2.390480459346185e-11"/>
        <axis xyz="0 0 1"/>
        <limit effort="56.0" lower="-6.283185307179586" upper="6.283185307179586" velocity="3.141592653589793"/>
        <dynamics damping="0" friction="0"/>
    </joint>
    <link name="ft_frame"/>
    <joint name="wrist_3_link-ft_frame" type="fixed">
        <parent link="wrist_3_link"/>
        <child link="ft_frame"/>
        <origin rpy="3.141592653589793 0 0" xyz="0 0 0"/>
    </joint>
    <!-- ROS-Industrial 'base' frame - base_link to UR 'Base' Coordinates transform -->
    <link name="base"/>
    <joint name="base_link-base_fixed_joint" type="fixed">
        <!-- Note the rotation over Z of pi radians - as base_link is REP-103
               aligned (i.e., has X+ forward, Y+ left and Z+ up), this is needed
               to correctly align 'base' with the 'Base' coordinate system of
               the UR controller.
          -->
        <origin rpy="0 0 3.141592653589793" xyz="0 0 0"/>
        <parent link="base_link"/>
        <child link="base"/>
    </joint>
    <!-- ROS-Industrial 'flange' frame - attachment point for EEF models -->
    <link name="flange"/>
    <joint name="wrist_3-flange" type="fixed">
        <parent link="wrist_3_link"/>
        <child link="flange"/>
        <origin rpy="0 -1.5707963267948966 -1.5707963267948966" xyz="0 0 0"/>
    </joint>
    <!-- ROS-Industrial 'tool0' frame - all-zeros tool frame -->
    <link name="tool0"/>
    <joint name="flange-tool0" type="fixed">
        <!-- default toolframe - X+ left, Y+ up, Z+ front -->
        <origin rpy="1.5707963267948966 0 1.5707963267948966" xyz="0 0 0"/>
        <parent link="flange"/>
        <child link="tool0"/>
    </joint>
    <joint name="tool1" type="fixed">
        <origin rpy="0 0 3.141592653589793" xyz="0.0 0.0 0.0"/>
        <parent link="tool0"/>
        <child link="cylinder_link"/>
    </joint>
    <link name="cylinder_link">
        <visual>
            <origin rpy="0 0 0" xyz="0 0 0"/>
            <geometry>
                <cylinder radius="0.01" length="0.2"/>
            </geometry>
            <material name="gray">
                <color rgba="0.5 0.5 0.5 1"/>
            </material>
        </visual>
    </link>
    <joint name="cylinder-tcp" type="fixed">
        <origin rpy="0 0 0" xyz="0.0 0.0 0.2"/>
        <parent link="cylinder_link"/>
        <child link="tcp_link"/>
    </joint>
    <link name="tcp_link"/>
</robot>

